/Library/Frameworks/Python.framework/Versions/3.9/lib/python3.9/site-packages/apscheduler/util.py:94: PytzUsageWarning: The zone attribute is specific to pytz's interface; please migrate to a new time zone provider. For more details on how to do so, see https://pytz-deprecation-shim.readthedocs.io/en/latest/migration.html
  if obj.zone == 'local':
/Library/Frameworks/Python.framework/Versions/3.9/lib/python3.9/site-packages/apscheduler/triggers/interval.py:66: PytzUsageWarning: The normalize method is no longer necessary, as this time zone supports the fold attribute (PEP 495). For more details on migrating to a PEP 495-compliant implementation, see https://pytz-deprecation-shim.readthedocs.io/en/latest/migration.html
  return self.timezone.normalize(next_fire_time)
/Library/Frameworks/Python.framework/Versions/3.9/lib/python3.9/site-packages/apscheduler/util.py:94: PytzUsageWarning: The zone attribute is specific to pytz's interface; please migrate to a new time zone provider. For more details on how to do so, see https://pytz-deprecation-shim.readthedocs.io/en/latest/migration.html
  if obj.zone == 'local':
/Library/Frameworks/Python.framework/Versions/3.9/lib/python3.9/site-packages/apscheduler/triggers/interval.py:66: PytzUsageWarning: The normalize method is no longer necessary, as this time zone supports the fold attribute (PEP 495). For more details on migrating to a PEP 495-compliant implementation, see https://pytz-deprecation-shim.readthedocs.io/en/latest/migration.html
  return self.timezone.normalize(next_fire_time)
Run time of job "check_2d (trigger: interval[0:01:00], next run at: 2021-12-07 11:11:11 KST)" was missed by 0:00:18.757166
Run time of job "check_2d (trigger: interval[0:01:00], next run at: 2021-12-07 11:56:11 KST)" was missed by 0:00:02.376302
Run time of job "check_2d (trigger: interval[0:01:00], next run at: 2021-12-07 12:44:11 KST)" was missed by 0:00:44.466552
Run time of job "check_2d (trigger: interval[0:01:00], next run at: 2021-12-07 13:01:11 KST)" was missed by 0:00:57.852066
/Library/Frameworks/Python.framework/Versions/3.9/lib/python3.9/site-packages/apscheduler/util.py:94: PytzUsageWarning: The zone attribute is specific to pytz's interface; please migrate to a new time zone provider. For more details on how to do so, see https://pytz-deprecation-shim.readthedocs.io/en/latest/migration.html
  if obj.zone == 'local':
/Library/Frameworks/Python.framework/Versions/3.9/lib/python3.9/site-packages/apscheduler/triggers/interval.py:66: PytzUsageWarning: The normalize method is no longer necessary, as this time zone supports the fold attribute (PEP 495). For more details on migrating to a PEP 495-compliant implementation, see https://pytz-deprecation-shim.readthedocs.io/en/latest/migration.html
  return self.timezone.normalize(next_fire_time)
/Library/Frameworks/Python.framework/Versions/3.9/lib/python3.9/site-packages/apscheduler/util.py:94: PytzUsageWarning: The zone attribute is specific to pytz's interface; please migrate to a new time zone provider. For more details on how to do so, see https://pytz-deprecation-shim.readthedocs.io/en/latest/migration.html
  if obj.zone == 'local':
/Library/Frameworks/Python.framework/Versions/3.9/lib/python3.9/site-packages/apscheduler/triggers/interval.py:66: PytzUsageWarning: The normalize method is no longer necessary, as this time zone supports the fold attribute (PEP 495). For more details on migrating to a PEP 495-compliant implementation, see https://pytz-deprecation-shim.readthedocs.io/en/latest/migration.html
  return self.timezone.normalize(next_fire_time)
Run time of job "check_2d (trigger: interval[0:01:00], next run at: 2021-12-07 14:07:18 KST)" was missed by 0:00:02.134617
Run time of job "check_2d (trigger: interval[0:01:00], next run at: 2021-12-07 15:00:18 KST)" was missed by 0:00:05.125362
Run time of job "check_2d (trigger: interval[0:01:00], next run at: 2021-12-07 15:34:18 KST)" was missed by 0:00:43.391923
Run time of job "check_2d (trigger: interval[0:01:00], next run at: 2021-12-07 15:41:18 KST)" was missed by 0:00:22.113558
Run time of job "check_2d (trigger: interval[0:01:00], next run at: 2021-12-07 16:05:18 KST)" was missed by 0:00:23.244753
Run time of job "check_2d (trigger: interval[0:01:00], next run at: 2021-12-07 16:32:18 KST)" was missed by 0:00:02.045067
Run time of job "check_2d (trigger: interval[0:01:00], next run at: 2021-12-07 19:00:18 KST)" was missed by 0:00:48.801466
Run time of job "check_2d (trigger: interval[0:01:00], next run at: 2021-12-07 19:20:18 KST)" was missed by 0:00:26.515504
Run time of job "check_2d (trigger: interval[0:01:00], next run at: 2021-12-07 19:25:18 KST)" was missed by 0:00:53.669557
Job "check_2d (trigger: interval[0:01:00], next run at: 2021-12-07 19:26:18 KST)" raised an exception
Traceback (most recent call last):
  File "/Library/Frameworks/Python.framework/Versions/3.9/lib/python3.9/site-packages/telegram/vendor/ptb_urllib3/urllib3/connectionpool.py", line 360, in _make_request
    self._validate_conn(conn)
  File "/Library/Frameworks/Python.framework/Versions/3.9/lib/python3.9/site-packages/telegram/vendor/ptb_urllib3/urllib3/connectionpool.py", line 857, in _validate_conn
    super(HTTPSConnectionPool, self)._validate_conn(conn)
  File "/Library/Frameworks/Python.framework/Versions/3.9/lib/python3.9/site-packages/telegram/vendor/ptb_urllib3/urllib3/connectionpool.py", line 289, in _validate_conn
    conn.connect()
  File "/Library/Frameworks/Python.framework/Versions/3.9/lib/python3.9/site-packages/telegram/vendor/ptb_urllib3/urllib3/connection.py", line 319, in connect
    self.sock = ssl_wrap_socket(
  File "/Library/Frameworks/Python.framework/Versions/3.9/lib/python3.9/site-packages/telegram/vendor/ptb_urllib3/urllib3/util/ssl_.py", line 324, in ssl_wrap_socket
    return context.wrap_socket(sock, server_hostname=server_hostname)
  File "/Library/Frameworks/Python.framework/Versions/3.9/lib/python3.9/ssl.py", line 500, in wrap_socket
    return self.sslsocket_class._create(
  File "/Library/Frameworks/Python.framework/Versions/3.9/lib/python3.9/ssl.py", line 1040, in _create
    self.do_handshake()
  File "/Library/Frameworks/Python.framework/Versions/3.9/lib/python3.9/ssl.py", line 1309, in do_handshake
    self._sslobj.do_handshake()
socket.timeout: _ssl.c:1112: The handshake operation timed out

During handling of the above exception, another exception occurred:

Traceback (most recent call last):
  File "/Library/Frameworks/Python.framework/Versions/3.9/lib/python3.9/site-packages/telegram/vendor/ptb_urllib3/urllib3/connectionpool.py", line 614, in urlopen
    httplib_response = self._make_request(conn, method, url,
  File "/Library/Frameworks/Python.framework/Versions/3.9/lib/python3.9/site-packages/telegram/vendor/ptb_urllib3/urllib3/connectionpool.py", line 363, in _make_request
    self._raise_timeout(err=e, url=url, timeout_value=conn.timeout,
  File "/Library/Frameworks/Python.framework/Versions/3.9/lib/python3.9/site-packages/telegram/vendor/ptb_urllib3/urllib3/connectionpool.py", line 321, in _raise_timeout
    raise exc_cls(*args)
telegram.vendor.ptb_urllib3.urllib3.exceptions.ConnectTimeoutError: (<telegram.vendor.ptb_urllib3.urllib3.connectionpool.HTTPSConnectionPool object at 0x7fa065afb8b0>, 'Connect timed out. (connect timeout=5.0)')

During handling of the above exception, another exception occurred:

Traceback (most recent call last):
  File "/Library/Frameworks/Python.framework/Versions/3.9/lib/python3.9/site-packages/telegram/utils/request.py", line 259, in _request_wrapper
    resp = self._con_pool.request(*args, **kwargs)
  File "/Library/Frameworks/Python.framework/Versions/3.9/lib/python3.9/site-packages/telegram/vendor/ptb_urllib3/urllib3/request.py", line 68, in request
    return self.request_encode_body(method, url, fields=fields,
  File "/Library/Frameworks/Python.framework/Versions/3.9/lib/python3.9/site-packages/telegram/vendor/ptb_urllib3/urllib3/request.py", line 148, in request_encode_body
    return self.urlopen(method, url, **extra_kw)
  File "/Library/Frameworks/Python.framework/Versions/3.9/lib/python3.9/site-packages/telegram/vendor/ptb_urllib3/urllib3/poolmanager.py", line 244, in urlopen
    response = conn.urlopen(method, u.request_uri, **kw)
  File "/Library/Frameworks/Python.framework/Versions/3.9/lib/python3.9/site-packages/telegram/vendor/ptb_urllib3/urllib3/connectionpool.py", line 691, in urlopen
    return self.urlopen(method, url, body, headers, retries,
  File "/Library/Frameworks/Python.framework/Versions/3.9/lib/python3.9/site-packages/telegram/vendor/ptb_urllib3/urllib3/connectionpool.py", line 691, in urlopen
    return self.urlopen(method, url, body, headers, retries,
  File "/Library/Frameworks/Python.framework/Versions/3.9/lib/python3.9/site-packages/telegram/vendor/ptb_urllib3/urllib3/connectionpool.py", line 691, in urlopen
    return self.urlopen(method, url, body, headers, retries,
  File "/Library/Frameworks/Python.framework/Versions/3.9/lib/python3.9/site-packages/telegram/vendor/ptb_urllib3/urllib3/connectionpool.py", line 665, in urlopen
    retries = retries.increment(method, url, error=e, _pool=self,
  File "/Library/Frameworks/Python.framework/Versions/3.9/lib/python3.9/site-packages/telegram/vendor/ptb_urllib3/urllib3/util/retry.py", line 376, in increment
    raise MaxRetryError(_pool, url, error or ResponseError(cause))
telegram.vendor.ptb_urllib3.urllib3.exceptions.MaxRetryError: HTTPSConnectionPool(host='api.telegram.org', port=443): Max retries exceeded with url: /bot5048329112:AAF4lvw_NfPr1zV74eD6ZtYD9yd6gHXYAMw/sendMessage (Caused by ConnectTimeoutError(<telegram.vendor.ptb_urllib3.urllib3.connectionpool.HTTPSConnectionPool object at 0x7fa065afb8b0>, 'Connect timed out. (connect timeout=5.0)'))

The above exception was the direct cause of the following exception:

Traceback (most recent call last):
  File "/Library/Frameworks/Python.framework/Versions/3.9/lib/python3.9/site-packages/apscheduler/executors/base.py", line 125, in run_job
    retval = job.func(*job.args, **job.kwargs)
  File "/Users/jskim2/Desktop/atom_algorithm/Algorithm/Movie_AlarmBot.py", line 43, in check_2d
    chatbot.sendMessage(chat_id=5064622110,text=j + " 의 예매가 오픈되었습니다.")
  File "/Library/Frameworks/Python.framework/Versions/3.9/lib/python3.9/site-packages/telegram/bot.py", line 130, in decorator
    result = func(*args, **kwargs)
  File "/Library/Frameworks/Python.framework/Versions/3.9/lib/python3.9/site-packages/telegram/bot.py", line 513, in send_message
    return self._message(  # type: ignore[return-value]
  File "/Library/Frameworks/Python.framework/Versions/3.9/lib/python3.9/site-packages/telegram/bot.py", line 332, in _message
    result = self._post(endpoint, data, timeout=timeout, api_kwargs=api_kwargs)
  File "/Library/Frameworks/Python.framework/Versions/3.9/lib/python3.9/site-packages/telegram/bot.py", line 295, in _post
    return self.request.post(
  File "/Library/Frameworks/Python.framework/Versions/3.9/lib/python3.9/site-packages/telegram/utils/request.py", line 361, in post
    result = self._request_wrapper(
  File "/Library/Frameworks/Python.framework/Versions/3.9/lib/python3.9/site-packages/telegram/utils/request.py", line 265, in _request_wrapper
    raise NetworkError(f'urllib3 HTTPError {error}') from error
telegram.error.NetworkError: urllib3 HTTPError HTTPSConnectionPool(host='api.telegram.org', port=443): Max retries exceeded with url: /bot5048329112:AAF4lvw_NfPr1zV74eD6ZtYD9yd6gHXYAMw/sendMessage (Caused by ConnectTimeoutError(<telegram.vendor.ptb_urllib3.urllib3.connectionpool.HTTPSConnectionPool object at 0x7fa065afb8b0>, 'Connect timed out. (connect timeout=5.0)'))
Run time of job "check_2d (trigger: interval[0:01:00], next run at: 2021-12-08 00:26:18 KST)" was missed by 0:00:47.407389
Run time of job "check_2d (trigger: interval[0:01:00], next run at: 2021-12-08 02:26:18 KST)" was missed by 0:00:57.127670
Job "check_2d (trigger: interval[0:01:00], next run at: 2021-12-08 02:27:18 KST)" raised an exception
Traceback (most recent call last):
  File "/Library/Frameworks/Python.framework/Versions/3.9/lib/python3.9/site-packages/telegram/vendor/ptb_urllib3/urllib3/connectionpool.py", line 360, in _make_request
    self._validate_conn(conn)
  File "/Library/Frameworks/Python.framework/Versions/3.9/lib/python3.9/site-packages/telegram/vendor/ptb_urllib3/urllib3/connectionpool.py", line 857, in _validate_conn
    super(HTTPSConnectionPool, self)._validate_conn(conn)
  File "/Library/Frameworks/Python.framework/Versions/3.9/lib/python3.9/site-packages/telegram/vendor/ptb_urllib3/urllib3/connectionpool.py", line 289, in _validate_conn
    conn.connect()
  File "/Library/Frameworks/Python.framework/Versions/3.9/lib/python3.9/site-packages/telegram/vendor/ptb_urllib3/urllib3/connection.py", line 319, in connect
    self.sock = ssl_wrap_socket(
  File "/Library/Frameworks/Python.framework/Versions/3.9/lib/python3.9/site-packages/telegram/vendor/ptb_urllib3/urllib3/util/ssl_.py", line 324, in ssl_wrap_socket
    return context.wrap_socket(sock, server_hostname=server_hostname)
  File "/Library/Frameworks/Python.framework/Versions/3.9/lib/python3.9/ssl.py", line 500, in wrap_socket
    return self.sslsocket_class._create(
  File "/Library/Frameworks/Python.framework/Versions/3.9/lib/python3.9/ssl.py", line 1040, in _create
    self.do_handshake()
  File "/Library/Frameworks/Python.framework/Versions/3.9/lib/python3.9/ssl.py", line 1309, in do_handshake
    self._sslobj.do_handshake()
socket.timeout: _ssl.c:1112: The handshake operation timed out

During handling of the above exception, another exception occurred:

Traceback (most recent call last):
  File "/Library/Frameworks/Python.framework/Versions/3.9/lib/python3.9/site-packages/telegram/vendor/ptb_urllib3/urllib3/connectionpool.py", line 614, in urlopen
    httplib_response = self._make_request(conn, method, url,
  File "/Library/Frameworks/Python.framework/Versions/3.9/lib/python3.9/site-packages/telegram/vendor/ptb_urllib3/urllib3/connectionpool.py", line 363, in _make_request
    self._raise_timeout(err=e, url=url, timeout_value=conn.timeout,
  File "/Library/Frameworks/Python.framework/Versions/3.9/lib/python3.9/site-packages/telegram/vendor/ptb_urllib3/urllib3/connectionpool.py", line 321, in _raise_timeout
    raise exc_cls(*args)
telegram.vendor.ptb_urllib3.urllib3.exceptions.ConnectTimeoutError: (<telegram.vendor.ptb_urllib3.urllib3.connectionpool.HTTPSConnectionPool object at 0x7fa0658b02b0>, 'Connect timed out. (connect timeout=5.0)')

During handling of the above exception, another exception occurred:

Traceback (most recent call last):
  File "/Library/Frameworks/Python.framework/Versions/3.9/lib/python3.9/site-packages/telegram/utils/request.py", line 259, in _request_wrapper
    resp = self._con_pool.request(*args, **kwargs)
  File "/Library/Frameworks/Python.framework/Versions/3.9/lib/python3.9/site-packages/telegram/vendor/ptb_urllib3/urllib3/request.py", line 68, in request
    return self.request_encode_body(method, url, fields=fields,
  File "/Library/Frameworks/Python.framework/Versions/3.9/lib/python3.9/site-packages/telegram/vendor/ptb_urllib3/urllib3/request.py", line 148, in request_encode_body
    return self.urlopen(method, url, **extra_kw)
  File "/Library/Frameworks/Python.framework/Versions/3.9/lib/python3.9/site-packages/telegram/vendor/ptb_urllib3/urllib3/poolmanager.py", line 244, in urlopen
    response = conn.urlopen(method, u.request_uri, **kw)
  File "/Library/Frameworks/Python.framework/Versions/3.9/lib/python3.9/site-packages/telegram/vendor/ptb_urllib3/urllib3/connectionpool.py", line 691, in urlopen
    return self.urlopen(method, url, body, headers, retries,
  File "/Library/Frameworks/Python.framework/Versions/3.9/lib/python3.9/site-packages/telegram/vendor/ptb_urllib3/urllib3/connectionpool.py", line 691, in urlopen
    return self.urlopen(method, url, body, headers, retries,
  File "/Library/Frameworks/Python.framework/Versions/3.9/lib/python3.9/site-packages/telegram/vendor/ptb_urllib3/urllib3/connectionpool.py", line 691, in urlopen
    return self.urlopen(method, url, body, headers, retries,
  File "/Library/Frameworks/Python.framework/Versions/3.9/lib/python3.9/site-packages/telegram/vendor/ptb_urllib3/urllib3/connectionpool.py", line 665, in urlopen
    retries = retries.increment(method, url, error=e, _pool=self,
  File "/Library/Frameworks/Python.framework/Versions/3.9/lib/python3.9/site-packages/telegram/vendor/ptb_urllib3/urllib3/util/retry.py", line 376, in increment
    raise MaxRetryError(_pool, url, error or ResponseError(cause))
telegram.vendor.ptb_urllib3.urllib3.exceptions.MaxRetryError: HTTPSConnectionPool(host='api.telegram.org', port=443): Max retries exceeded with url: /bot5048329112:AAF4lvw_NfPr1zV74eD6ZtYD9yd6gHXYAMw/sendMessage (Caused by ConnectTimeoutError(<telegram.vendor.ptb_urllib3.urllib3.connectionpool.HTTPSConnectionPool object at 0x7fa0658b02b0>, 'Connect timed out. (connect timeout=5.0)'))

The above exception was the direct cause of the following exception:

Traceback (most recent call last):
  File "/Library/Frameworks/Python.framework/Versions/3.9/lib/python3.9/site-packages/apscheduler/executors/base.py", line 125, in run_job
    retval = job.func(*job.args, **job.kwargs)
  File "/Users/jskim2/Desktop/atom_algorithm/Algorithm/Movie_AlarmBot.py", line 43, in check_2d
    chatbot.sendMessage(chat_id=5064622110,text=j + " 의 예매가 오픈되었습니다.")
  File "/Library/Frameworks/Python.framework/Versions/3.9/lib/python3.9/site-packages/telegram/bot.py", line 130, in decorator
    result = func(*args, **kwargs)
  File "/Library/Frameworks/Python.framework/Versions/3.9/lib/python3.9/site-packages/telegram/bot.py", line 513, in send_message
    return self._message(  # type: ignore[return-value]
  File "/Library/Frameworks/Python.framework/Versions/3.9/lib/python3.9/site-packages/telegram/bot.py", line 332, in _message
    result = self._post(endpoint, data, timeout=timeout, api_kwargs=api_kwargs)
  File "/Library/Frameworks/Python.framework/Versions/3.9/lib/python3.9/site-packages/telegram/bot.py", line 295, in _post
    return self.request.post(
  File "/Library/Frameworks/Python.framework/Versions/3.9/lib/python3.9/site-packages/telegram/utils/request.py", line 361, in post
    result = self._request_wrapper(
  File "/Library/Frameworks/Python.framework/Versions/3.9/lib/python3.9/site-packages/telegram/utils/request.py", line 265, in _request_wrapper
    raise NetworkError(f'urllib3 HTTPError {error}') from error
telegram.error.NetworkError: urllib3 HTTPError HTTPSConnectionPool(host='api.telegram.org', port=443): Max retries exceeded with url: /bot5048329112:AAF4lvw_NfPr1zV74eD6ZtYD9yd6gHXYAMw/sendMessage (Caused by ConnectTimeoutError(<telegram.vendor.ptb_urllib3.urllib3.connectionpool.HTTPSConnectionPool object at 0x7fa0658b02b0>, 'Connect timed out. (connect timeout=5.0)'))
Run time of job "check_2d (trigger: interval[0:01:00], next run at: 2021-12-08 06:27:18 KST)" was missed by 0:00:35.793215
Run time of job "check_2d (trigger: interval[0:01:00], next run at: 2021-12-08 07:27:18 KST)" was missed by 0:00:56.079657
Run time of job "check_2d (trigger: interval[0:01:00], next run at: 2021-12-08 10:19:18 KST)" was missed by 0:00:34.539785
